[2024-12-26T17:47:32.212+0000] {local_task_job_runner.py:123} INFO - ::group::Pre task execution logs
[2024-12-26T17:47:32.243+0000] {taskinstance.py:2613} INFO - Dependencies all met for dep_context=non-requeueable deps ti=<TaskInstance: my_python_app_dag.run_my_python_app manual__2024-12-26T17:47:30.890028+00:00 [queued]>
[2024-12-26T17:47:32.256+0000] {taskinstance.py:2613} INFO - Dependencies all met for dep_context=requeueable deps ti=<TaskInstance: my_python_app_dag.run_my_python_app manual__2024-12-26T17:47:30.890028+00:00 [queued]>
[2024-12-26T17:47:32.256+0000] {taskinstance.py:2866} INFO - Starting attempt 1 of 2
[2024-12-26T17:47:32.274+0000] {taskinstance.py:2889} INFO - Executing <Task(DockerOperator): run_my_python_app> on 2024-12-26 17:47:30.890028+00:00
[2024-12-26T17:47:32.287+0000] {logging_mixin.py:190} WARNING - /home/***/.local/lib/python3.12/site-packages/***/task/task_runner/standard_task_runner.py:70 DeprecationWarning: This process (pid=3080) is multi-threaded, use of fork() may lead to deadlocks in the child.
[2024-12-26T17:47:32.288+0000] {standard_task_runner.py:72} INFO - Started process 3081 to run task
[2024-12-26T17:47:32.291+0000] {standard_task_runner.py:104} INFO - Running: ['***', 'tasks', 'run', 'my_python_app_dag', 'run_my_python_app', 'manual__2024-12-26T17:47:30.890028+00:00', '--job-id', '529', '--raw', '--subdir', 'DAGS_FOLDER/dag_my-python-app.py', '--cfg-path', '/tmp/tmpx58nul84']
[2024-12-26T17:47:32.297+0000] {standard_task_runner.py:105} INFO - Job 529: Subtask run_my_python_app
[2024-12-26T17:47:32.392+0000] {task_command.py:467} INFO - Running <TaskInstance: my_python_app_dag.run_my_python_app manual__2024-12-26T17:47:30.890028+00:00 [running]> on host 1484ae97611b
[2024-12-26T17:47:32.566+0000] {taskinstance.py:3132} INFO - Exporting env vars: AIRFLOW_CTX_DAG_OWNER='***' AIRFLOW_CTX_DAG_ID='my_python_app_dag' AIRFLOW_CTX_TASK_ID='run_my_python_app' AIRFLOW_CTX_EXECUTION_DATE='2024-12-26T17:47:30.890028+00:00' AIRFLOW_CTX_TRY_NUMBER='1' AIRFLOW_CTX_DAG_RUN_ID='manual__2024-12-26T17:47:30.890028+00:00'
[2024-12-26T17:47:32.567+0000] {taskinstance.py:731} INFO - ::endgroup::
[2024-12-26T17:47:32.617+0000] {docker.py:379} INFO - Starting docker container from image my-python-app:latest
[2024-12-26T17:47:32.627+0000] {docker.py:387} WARNING - Using remote engine or docker-in-docker and mounting temporary volume from host is not supported. Falling back to `mount_tmp_dir=False` mode. You can set `mount_tmp_dir` parameter to False to disable mounting and remove the warning
[2024-12-26T17:47:33.037+0000] {docker.py:73} INFO - ISSO AQUI É A APLICAÇÃO RODANDO!!!!!!!!!1.
[2024-12-26T17:47:33.382+0000] {taskinstance.py:340} INFO - ::group::Post task execution logs
[2024-12-26T17:47:33.384+0000] {taskinstance.py:352} INFO - Marking task as SUCCESS. dag_id=my_python_app_dag, task_id=run_my_python_app, run_id=manual__2024-12-26T17:47:30.890028+00:00, execution_date=20241226T174730, start_date=20241226T174732, end_date=20241226T174733
[2024-12-26T17:47:33.426+0000] {local_task_job_runner.py:266} INFO - Task exited with return code 0
[2024-12-26T17:47:33.465+0000] {taskinstance.py:3895} INFO - 0 downstream tasks scheduled from follow-on schedule check
[2024-12-26T17:47:33.467+0000] {local_task_job_runner.py:245} INFO - ::endgroup::
