[2024-12-27T14:27:44.064-0300] {local_task_job_runner.py:123} INFO - ::group::Pre task execution logs
[2024-12-27T14:27:44.094-0300] {taskinstance.py:2613} INFO - Dependencies all met for dep_context=non-requeueable deps ti=<TaskInstance: diario_oficial.run_diario_oficial manual__2024-12-27T14:22:41.735296-03:00 [queued]>
[2024-12-27T14:27:44.110-0300] {taskinstance.py:2613} INFO - Dependencies all met for dep_context=requeueable deps ti=<TaskInstance: diario_oficial.run_diario_oficial manual__2024-12-27T14:22:41.735296-03:00 [queued]>
[2024-12-27T14:27:44.111-0300] {taskinstance.py:2866} INFO - Starting attempt 2 of 2
[2024-12-27T14:27:44.135-0300] {taskinstance.py:2889} INFO - Executing <Task(DockerOperator): run_diario_oficial> on 2024-12-27 14:22:41.735296-03:00
[2024-12-27T14:27:44.155-0300] {logging_mixin.py:190} WARNING - /home/***/.local/lib/python3.12/site-packages/***/task/task_runner/standard_task_runner.py:70 DeprecationWarning: This process (pid=6322) is multi-threaded, use of fork() may lead to deadlocks in the child.
[2024-12-27T14:27:44.156-0300] {standard_task_runner.py:72} INFO - Started process 6323 to run task
[2024-12-27T14:27:44.155-0300] {standard_task_runner.py:104} INFO - Running: ['***', 'tasks', 'run', 'diario_oficial', 'run_diario_oficial', 'manual__2024-12-27T14:22:41.735296-03:00', '--job-id', '348', '--raw', '--subdir', 'DAGS_FOLDER/dag_diario_oficial.py', '--cfg-path', '/tmp/tmpt2vyg7lt']
[2024-12-27T14:27:44.160-0300] {standard_task_runner.py:105} INFO - Job 348: Subtask run_diario_oficial
[2024-12-27T14:27:44.248-0300] {task_command.py:467} INFO - Running <TaskInstance: diario_oficial.run_diario_oficial manual__2024-12-27T14:22:41.735296-03:00 [running]> on host f657cc3f60f7
[2024-12-27T14:27:44.411-0300] {taskinstance.py:3132} INFO - Exporting env vars: AIRFLOW_CTX_DAG_OWNER='***' AIRFLOW_CTX_DAG_ID='diario_oficial' AIRFLOW_CTX_TASK_ID='run_diario_oficial' AIRFLOW_CTX_EXECUTION_DATE='2024-12-27T14:22:41.735296-03:00' AIRFLOW_CTX_TRY_NUMBER='2' AIRFLOW_CTX_DAG_RUN_ID='manual__2024-12-27T14:22:41.735296-03:00'
[2024-12-27T14:27:44.412-0300] {taskinstance.py:731} INFO - ::endgroup::
[2024-12-27T14:27:44.468-0300] {docker.py:379} INFO - Starting docker container from image diario-oficial:latest
[2024-12-27T14:27:44.819-0300] {docker.py:73} INFO - Traceback (most recent call last):
[2024-12-27T14:27:44.819-0300] {docker.py:73} INFO -   File "/diario_oficial/diario_oficial/cli.py", line 1, in <module>
[2024-12-27T14:27:44.820-0300] {docker.py:73} INFO -     import typer
[2024-12-27T14:27:44.820-0300] {docker.py:73} INFO - ModuleNotFoundError: No module named 'typer'
[2024-12-27T14:27:45.126-0300] {taskinstance.py:3311} ERROR - Task failed with exception
Traceback (most recent call last):
  File "/home/airflow/.local/lib/python3.12/site-packages/airflow/models/taskinstance.py", line 767, in _execute_task
    result = _execute_callable(context=context, **execute_callable_kwargs)
             ^^^^^^^^^^^^^^^^^^^^^^^^^^^^^^^^^^^^^^^^^^^^^^^^^^^^^^^^^^^^^
  File "/home/airflow/.local/lib/python3.12/site-packages/airflow/models/taskinstance.py", line 733, in _execute_callable
    return ExecutionCallableRunner(
           ^^^^^^^^^^^^^^^^^^^^^^^^
  File "/home/airflow/.local/lib/python3.12/site-packages/airflow/utils/operator_helpers.py", line 252, in run
    return self.func(*args, **kwargs)
           ^^^^^^^^^^^^^^^^^^^^^^^^^^
  File "/home/airflow/.local/lib/python3.12/site-packages/airflow/models/baseoperator.py", line 422, in wrapper
    return func(self, *args, **kwargs)
           ^^^^^^^^^^^^^^^^^^^^^^^^^^^
  File "/home/airflow/.local/lib/python3.12/site-packages/airflow/providers/docker/operators/docker.py", line 519, in execute
    return self._run_image()
           ^^^^^^^^^^^^^^^^^
  File "/home/airflow/.local/lib/python3.12/site-packages/airflow/providers/docker/operators/docker.py", line 396, in _run_image
    return self._run_image_with_mounts(self.mounts, add_tmp_variable=False)
           ^^^^^^^^^^^^^^^^^^^^^^^^^^^^^^^^^^^^^^^^^^^^^^^^^^^^^^^^^^^^^^^^
  File "/home/airflow/.local/lib/python3.12/site-packages/airflow/providers/docker/operators/docker.py", line 453, in _run_image_with_mounts
    raise DockerContainerFailedException(f"Docker container failed: {result!r}", logs=log_lines)
airflow.providers.docker.exceptions.DockerContainerFailedException: Docker container failed: {'StatusCode': 1}
[2024-12-27T14:27:45.135-0300] {taskinstance.py:1225} INFO - Marking task as FAILED. dag_id=diario_oficial, task_id=run_diario_oficial, run_id=manual__2024-12-27T14:22:41.735296-03:00, execution_date=20241227T142241, start_date=20241227T142744, end_date=20241227T142745
[2024-12-27T14:27:45.157-0300] {taskinstance.py:340} INFO - ::group::Post task execution logs
[2024-12-27T14:27:45.158-0300] {standard_task_runner.py:124} ERROR - Failed to execute job 348 for task run_diario_oficial (Docker container failed: {'StatusCode': 1}; 6323)
Traceback (most recent call last):
  File "/home/airflow/.local/lib/python3.12/site-packages/airflow/task/task_runner/standard_task_runner.py", line 117, in _start_by_fork
    ret = args.func(args, dag=self.dag)
          ^^^^^^^^^^^^^^^^^^^^^^^^^^^^^
  File "/home/airflow/.local/lib/python3.12/site-packages/airflow/cli/cli_config.py", line 49, in command
    return func(*args, **kwargs)
           ^^^^^^^^^^^^^^^^^^^^^
  File "/home/airflow/.local/lib/python3.12/site-packages/airflow/utils/cli.py", line 116, in wrapper
    return f(*args, **kwargs)
           ^^^^^^^^^^^^^^^^^^
  File "/home/airflow/.local/lib/python3.12/site-packages/airflow/cli/commands/task_command.py", line 483, in task_run
    task_return_code = _run_task_by_selected_method(args, _dag, ti)
                       ^^^^^^^^^^^^^^^^^^^^^^^^^^^^^^^^^^^^^^^^^^^^
  File "/home/airflow/.local/lib/python3.12/site-packages/airflow/cli/commands/task_command.py", line 256, in _run_task_by_selected_method
    return _run_raw_task(args, ti)
           ^^^^^^^^^^^^^^^^^^^^^^^
  File "/home/airflow/.local/lib/python3.12/site-packages/airflow/cli/commands/task_command.py", line 341, in _run_raw_task
    return ti._run_raw_task(
           ^^^^^^^^^^^^^^^^^
  File "/home/airflow/.local/lib/python3.12/site-packages/airflow/utils/session.py", line 97, in wrapper
    return func(*args, session=session, **kwargs)
           ^^^^^^^^^^^^^^^^^^^^^^^^^^^^^^^^^^^^^^
  File "/home/airflow/.local/lib/python3.12/site-packages/airflow/models/taskinstance.py", line 3005, in _run_raw_task
    return _run_raw_task(
           ^^^^^^^^^^^^^^
  File "/home/airflow/.local/lib/python3.12/site-packages/airflow/models/taskinstance.py", line 273, in _run_raw_task
    TaskInstance._execute_task_with_callbacks(
  File "/home/airflow/.local/lib/python3.12/site-packages/airflow/models/taskinstance.py", line 3159, in _execute_task_with_callbacks
    result = self._execute_task(context, task_orig)
             ^^^^^^^^^^^^^^^^^^^^^^^^^^^^^^^^^^^^^^
  File "/home/airflow/.local/lib/python3.12/site-packages/airflow/models/taskinstance.py", line 3183, in _execute_task
    return _execute_task(self, context, task_orig)
           ^^^^^^^^^^^^^^^^^^^^^^^^^^^^^^^^^^^^^^^
  File "/home/airflow/.local/lib/python3.12/site-packages/airflow/models/taskinstance.py", line 767, in _execute_task
    result = _execute_callable(context=context, **execute_callable_kwargs)
             ^^^^^^^^^^^^^^^^^^^^^^^^^^^^^^^^^^^^^^^^^^^^^^^^^^^^^^^^^^^^^
  File "/home/airflow/.local/lib/python3.12/site-packages/airflow/models/taskinstance.py", line 733, in _execute_callable
    return ExecutionCallableRunner(
           ^^^^^^^^^^^^^^^^^^^^^^^^
  File "/home/airflow/.local/lib/python3.12/site-packages/airflow/utils/operator_helpers.py", line 252, in run
    return self.func(*args, **kwargs)
           ^^^^^^^^^^^^^^^^^^^^^^^^^^
  File "/home/airflow/.local/lib/python3.12/site-packages/airflow/models/baseoperator.py", line 422, in wrapper
    return func(self, *args, **kwargs)
           ^^^^^^^^^^^^^^^^^^^^^^^^^^^
  File "/home/airflow/.local/lib/python3.12/site-packages/airflow/providers/docker/operators/docker.py", line 519, in execute
    return self._run_image()
           ^^^^^^^^^^^^^^^^^
  File "/home/airflow/.local/lib/python3.12/site-packages/airflow/providers/docker/operators/docker.py", line 396, in _run_image
    return self._run_image_with_mounts(self.mounts, add_tmp_variable=False)
           ^^^^^^^^^^^^^^^^^^^^^^^^^^^^^^^^^^^^^^^^^^^^^^^^^^^^^^^^^^^^^^^^
  File "/home/airflow/.local/lib/python3.12/site-packages/airflow/providers/docker/operators/docker.py", line 453, in _run_image_with_mounts
    raise DockerContainerFailedException(f"Docker container failed: {result!r}", logs=log_lines)
airflow.providers.docker.exceptions.DockerContainerFailedException: Docker container failed: {'StatusCode': 1}
[2024-12-27T14:27:45.215-0300] {local_task_job_runner.py:266} INFO - Task exited with return code 1
[2024-12-27T14:27:45.254-0300] {taskinstance.py:3895} INFO - 0 downstream tasks scheduled from follow-on schedule check
[2024-12-27T14:27:45.256-0300] {local_task_job_runner.py:245} INFO - ::endgroup::
