[2024-12-26T17:06:33.246-0300] {local_task_job_runner.py:123} INFO - ::group::Pre task execution logs
[2024-12-26T17:06:33.275-0300] {taskinstance.py:2613} INFO - Dependencies all met for dep_context=non-requeueable deps ti=<TaskInstance: my_python_app_dag.run_my_python_app manual__2024-12-26T17:06:32.118627-03:00 [queued]>
[2024-12-26T17:06:33.293-0300] {taskinstance.py:2613} INFO - Dependencies all met for dep_context=requeueable deps ti=<TaskInstance: my_python_app_dag.run_my_python_app manual__2024-12-26T17:06:32.118627-03:00 [queued]>
[2024-12-26T17:06:33.293-0300] {taskinstance.py:2866} INFO - Starting attempt 1 of 2
[2024-12-26T17:06:33.313-0300] {taskinstance.py:2889} INFO - Executing <Task(DockerOperator): run_my_python_app> on 2024-12-26 17:06:32.118627-03:00
[2024-12-26T17:06:33.332-0300] {logging_mixin.py:190} WARNING - /home/***/.local/lib/python3.12/site-packages/***/task/task_runner/standard_task_runner.py:70 DeprecationWarning: This process (pid=2027) is multi-threaded, use of fork() may lead to deadlocks in the child.
[2024-12-26T17:06:33.333-0300] {standard_task_runner.py:72} INFO - Started process 2028 to run task
[2024-12-26T17:06:33.332-0300] {standard_task_runner.py:104} INFO - Running: ['***', 'tasks', 'run', 'my_python_app_dag', 'run_my_python_app', 'manual__2024-12-26T17:06:32.118627-03:00', '--job-id', '541', '--raw', '--subdir', 'DAGS_FOLDER/dag_my-python-app.py', '--cfg-path', '/tmp/tmpd7im7phz']
[2024-12-26T17:06:33.337-0300] {standard_task_runner.py:105} INFO - Job 541: Subtask run_my_python_app
[2024-12-26T17:06:33.430-0300] {task_command.py:467} INFO - Running <TaskInstance: my_python_app_dag.run_my_python_app manual__2024-12-26T17:06:32.118627-03:00 [running]> on host 1a6bcaf2dced
[2024-12-26T17:06:33.615-0300] {taskinstance.py:3132} INFO - Exporting env vars: AIRFLOW_CTX_DAG_OWNER='***' AIRFLOW_CTX_DAG_ID='my_python_app_dag' AIRFLOW_CTX_TASK_ID='run_my_python_app' AIRFLOW_CTX_EXECUTION_DATE='2024-12-26T17:06:32.118627-03:00' AIRFLOW_CTX_TRY_NUMBER='1' AIRFLOW_CTX_DAG_RUN_ID='manual__2024-12-26T17:06:32.118627-03:00'
[2024-12-26T17:06:33.616-0300] {taskinstance.py:731} INFO - ::endgroup::
[2024-12-26T17:06:33.674-0300] {docker.py:379} INFO - Starting docker container from image diario-oficial:latest
[2024-12-26T17:06:34.621-0300] {docker.py:73} INFO - /root/.cache/pypoetry/virtualenvs/diario-oficial-srfFVHAc-py3.12/bin/python: can't open file '/diario_oficial/src/main.py': [Errno 2] No such file or directory
[2024-12-26T17:06:34.905-0300] {taskinstance.py:3311} ERROR - Task failed with exception
Traceback (most recent call last):
  File "/home/airflow/.local/lib/python3.12/site-packages/airflow/models/taskinstance.py", line 767, in _execute_task
    result = _execute_callable(context=context, **execute_callable_kwargs)
             ^^^^^^^^^^^^^^^^^^^^^^^^^^^^^^^^^^^^^^^^^^^^^^^^^^^^^^^^^^^^^
  File "/home/airflow/.local/lib/python3.12/site-packages/airflow/models/taskinstance.py", line 733, in _execute_callable
    return ExecutionCallableRunner(
           ^^^^^^^^^^^^^^^^^^^^^^^^
  File "/home/airflow/.local/lib/python3.12/site-packages/airflow/utils/operator_helpers.py", line 252, in run
    return self.func(*args, **kwargs)
           ^^^^^^^^^^^^^^^^^^^^^^^^^^
  File "/home/airflow/.local/lib/python3.12/site-packages/airflow/models/baseoperator.py", line 422, in wrapper
    return func(self, *args, **kwargs)
           ^^^^^^^^^^^^^^^^^^^^^^^^^^^
  File "/home/airflow/.local/lib/python3.12/site-packages/airflow/providers/docker/operators/docker.py", line 519, in execute
    return self._run_image()
           ^^^^^^^^^^^^^^^^^
  File "/home/airflow/.local/lib/python3.12/site-packages/airflow/providers/docker/operators/docker.py", line 396, in _run_image
    return self._run_image_with_mounts(self.mounts, add_tmp_variable=False)
           ^^^^^^^^^^^^^^^^^^^^^^^^^^^^^^^^^^^^^^^^^^^^^^^^^^^^^^^^^^^^^^^^
  File "/home/airflow/.local/lib/python3.12/site-packages/airflow/providers/docker/operators/docker.py", line 453, in _run_image_with_mounts
    raise DockerContainerFailedException(f"Docker container failed: {result!r}", logs=log_lines)
airflow.providers.docker.exceptions.DockerContainerFailedException: Docker container failed: {'StatusCode': 2}
[2024-12-26T17:06:34.921-0300] {taskinstance.py:1225} INFO - Marking task as UP_FOR_RETRY. dag_id=my_python_app_dag, task_id=run_my_python_app, run_id=manual__2024-12-26T17:06:32.118627-03:00, execution_date=20241226T170632, start_date=20241226T170633, end_date=20241226T170634
[2024-12-26T17:06:34.947-0300] {taskinstance.py:340} INFO - ::group::Post task execution logs
[2024-12-26T17:06:34.948-0300] {standard_task_runner.py:124} ERROR - Failed to execute job 541 for task run_my_python_app (Docker container failed: {'StatusCode': 2}; 2028)
Traceback (most recent call last):
  File "/home/airflow/.local/lib/python3.12/site-packages/airflow/task/task_runner/standard_task_runner.py", line 117, in _start_by_fork
    ret = args.func(args, dag=self.dag)
          ^^^^^^^^^^^^^^^^^^^^^^^^^^^^^
  File "/home/airflow/.local/lib/python3.12/site-packages/airflow/cli/cli_config.py", line 49, in command
    return func(*args, **kwargs)
           ^^^^^^^^^^^^^^^^^^^^^
  File "/home/airflow/.local/lib/python3.12/site-packages/airflow/utils/cli.py", line 116, in wrapper
    return f(*args, **kwargs)
           ^^^^^^^^^^^^^^^^^^
  File "/home/airflow/.local/lib/python3.12/site-packages/airflow/cli/commands/task_command.py", line 483, in task_run
    task_return_code = _run_task_by_selected_method(args, _dag, ti)
                       ^^^^^^^^^^^^^^^^^^^^^^^^^^^^^^^^^^^^^^^^^^^^
  File "/home/airflow/.local/lib/python3.12/site-packages/airflow/cli/commands/task_command.py", line 256, in _run_task_by_selected_method
    return _run_raw_task(args, ti)
           ^^^^^^^^^^^^^^^^^^^^^^^
  File "/home/airflow/.local/lib/python3.12/site-packages/airflow/cli/commands/task_command.py", line 341, in _run_raw_task
    return ti._run_raw_task(
           ^^^^^^^^^^^^^^^^^
  File "/home/airflow/.local/lib/python3.12/site-packages/airflow/utils/session.py", line 97, in wrapper
    return func(*args, session=session, **kwargs)
           ^^^^^^^^^^^^^^^^^^^^^^^^^^^^^^^^^^^^^^
  File "/home/airflow/.local/lib/python3.12/site-packages/airflow/models/taskinstance.py", line 3005, in _run_raw_task
    return _run_raw_task(
           ^^^^^^^^^^^^^^
  File "/home/airflow/.local/lib/python3.12/site-packages/airflow/models/taskinstance.py", line 273, in _run_raw_task
    TaskInstance._execute_task_with_callbacks(
  File "/home/airflow/.local/lib/python3.12/site-packages/airflow/models/taskinstance.py", line 3159, in _execute_task_with_callbacks
    result = self._execute_task(context, task_orig)
             ^^^^^^^^^^^^^^^^^^^^^^^^^^^^^^^^^^^^^^
  File "/home/airflow/.local/lib/python3.12/site-packages/airflow/models/taskinstance.py", line 3183, in _execute_task
    return _execute_task(self, context, task_orig)
           ^^^^^^^^^^^^^^^^^^^^^^^^^^^^^^^^^^^^^^^
  File "/home/airflow/.local/lib/python3.12/site-packages/airflow/models/taskinstance.py", line 767, in _execute_task
    result = _execute_callable(context=context, **execute_callable_kwargs)
             ^^^^^^^^^^^^^^^^^^^^^^^^^^^^^^^^^^^^^^^^^^^^^^^^^^^^^^^^^^^^^
  File "/home/airflow/.local/lib/python3.12/site-packages/airflow/models/taskinstance.py", line 733, in _execute_callable
    return ExecutionCallableRunner(
           ^^^^^^^^^^^^^^^^^^^^^^^^
  File "/home/airflow/.local/lib/python3.12/site-packages/airflow/utils/operator_helpers.py", line 252, in run
    return self.func(*args, **kwargs)
           ^^^^^^^^^^^^^^^^^^^^^^^^^^
  File "/home/airflow/.local/lib/python3.12/site-packages/airflow/models/baseoperator.py", line 422, in wrapper
    return func(self, *args, **kwargs)
           ^^^^^^^^^^^^^^^^^^^^^^^^^^^
  File "/home/airflow/.local/lib/python3.12/site-packages/airflow/providers/docker/operators/docker.py", line 519, in execute
    return self._run_image()
           ^^^^^^^^^^^^^^^^^
  File "/home/airflow/.local/lib/python3.12/site-packages/airflow/providers/docker/operators/docker.py", line 396, in _run_image
    return self._run_image_with_mounts(self.mounts, add_tmp_variable=False)
           ^^^^^^^^^^^^^^^^^^^^^^^^^^^^^^^^^^^^^^^^^^^^^^^^^^^^^^^^^^^^^^^^
  File "/home/airflow/.local/lib/python3.12/site-packages/airflow/providers/docker/operators/docker.py", line 453, in _run_image_with_mounts
    raise DockerContainerFailedException(f"Docker container failed: {result!r}", logs=log_lines)
airflow.providers.docker.exceptions.DockerContainerFailedException: Docker container failed: {'StatusCode': 2}
[2024-12-26T17:06:34.993-0300] {local_task_job_runner.py:266} INFO - Task exited with return code 1
[2024-12-26T17:06:35.041-0300] {taskinstance.py:3895} INFO - 0 downstream tasks scheduled from follow-on schedule check
[2024-12-26T17:06:35.043-0300] {local_task_job_runner.py:245} INFO - ::endgroup::
