[2024-12-27T09:55:55.777-0300] {local_task_job_runner.py:123} INFO - ::group::Pre task execution logs
[2024-12-27T09:55:55.812-0300] {taskinstance.py:2613} INFO - Dependencies all met for dep_context=non-requeueable deps ti=<TaskInstance: my_python_app_dag.run_my_python_app scheduled__2024-12-26T00:00:00-03:00 [queued]>
[2024-12-27T09:55:55.826-0300] {taskinstance.py:2613} INFO - Dependencies all met for dep_context=requeueable deps ti=<TaskInstance: my_python_app_dag.run_my_python_app scheduled__2024-12-26T00:00:00-03:00 [queued]>
[2024-12-27T09:55:55.827-0300] {taskinstance.py:2866} INFO - Starting attempt 1 of 2
[2024-12-27T09:55:55.845-0300] {taskinstance.py:2889} INFO - Executing <Task(DockerOperator): run_my_python_app> on 2024-12-26 00:00:00-03:00
[2024-12-27T09:55:55.858-0300] {logging_mixin.py:190} WARNING - /home/***/.local/lib/python3.12/site-packages/***/task/task_runner/standard_task_runner.py:70 DeprecationWarning: This process (pid=202) is multi-threaded, use of fork() may lead to deadlocks in the child.
[2024-12-27T09:55:55.858-0300] {standard_task_runner.py:72} INFO - Started process 213 to run task
[2024-12-27T09:55:55.857-0300] {standard_task_runner.py:104} INFO - Running: ['***', 'tasks', 'run', 'my_python_app_dag', 'run_my_python_app', 'scheduled__2024-12-26T00:00:00-03:00', '--job-id', '564', '--raw', '--subdir', 'DAGS_FOLDER/dag_my-python-app.py', '--cfg-path', '/tmp/tmprr535o7e']
[2024-12-27T09:55:55.861-0300] {standard_task_runner.py:105} INFO - Job 564: Subtask run_my_python_app
[2024-12-27T09:55:55.942-0300] {task_command.py:467} INFO - Running <TaskInstance: my_python_app_dag.run_my_python_app scheduled__2024-12-26T00:00:00-03:00 [running]> on host 1a6bcaf2dced
[2024-12-27T09:55:56.089-0300] {taskinstance.py:3132} INFO - Exporting env vars: AIRFLOW_CTX_DAG_OWNER='***' AIRFLOW_CTX_DAG_ID='my_python_app_dag' AIRFLOW_CTX_TASK_ID='run_my_python_app' AIRFLOW_CTX_EXECUTION_DATE='2024-12-26T00:00:00-03:00' AIRFLOW_CTX_TRY_NUMBER='1' AIRFLOW_CTX_DAG_RUN_ID='scheduled__2024-12-26T00:00:00-03:00'
[2024-12-27T09:55:56.090-0300] {taskinstance.py:731} INFO - ::endgroup::
[2024-12-27T09:55:56.117-0300] {docker.py:157} ERROR - Failed to establish connection to Docker host unix://var/run/docker.sock: Error while fetching server API version: ('Connection aborted.', PermissionError(13, 'Permission denied'))
[2024-12-27T09:55:56.131-0300] {taskinstance.py:3311} ERROR - Task failed with exception
Traceback (most recent call last):
  File "/home/airflow/.local/lib/python3.12/site-packages/airflow/models/taskinstance.py", line 767, in _execute_task
    result = _execute_callable(context=context, **execute_callable_kwargs)
             ^^^^^^^^^^^^^^^^^^^^^^^^^^^^^^^^^^^^^^^^^^^^^^^^^^^^^^^^^^^^^
  File "/home/airflow/.local/lib/python3.12/site-packages/airflow/models/taskinstance.py", line 733, in _execute_callable
    return ExecutionCallableRunner(
           ^^^^^^^^^^^^^^^^^^^^^^^^
  File "/home/airflow/.local/lib/python3.12/site-packages/airflow/utils/operator_helpers.py", line 252, in run
    return self.func(*args, **kwargs)
           ^^^^^^^^^^^^^^^^^^^^^^^^^^
  File "/home/airflow/.local/lib/python3.12/site-packages/airflow/models/baseoperator.py", line 422, in wrapper
    return func(self, *args, **kwargs)
           ^^^^^^^^^^^^^^^^^^^^^^^^^^^
  File "/home/airflow/.local/lib/python3.12/site-packages/airflow/providers/docker/operators/docker.py", line 501, in execute
    if self.force_pull or not self.cli.images(name=self.image):
                              ^^^^^^^^
  File "/home/airflow/.local/lib/python3.12/site-packages/airflow/providers/docker/operators/docker.py", line 375, in cli
    return self.hook.api_client
           ^^^^^^^^^^^^^^^^^^^^
  File "/usr/local/lib/python3.12/functools.py", line 995, in __get__
    val = self.func(instance)
          ^^^^^^^^^^^^^^^^^^^
  File "/home/airflow/.local/lib/python3.12/site-packages/airflow/providers/docker/hooks/docker.py", line 161, in api_client
    raise AirflowException("Failed to establish connection to any given Docker hosts.")
airflow.exceptions.AirflowException: Failed to establish connection to any given Docker hosts.
[2024-12-27T09:55:56.144-0300] {taskinstance.py:1225} INFO - Marking task as UP_FOR_RETRY. dag_id=my_python_app_dag, task_id=run_my_python_app, run_id=scheduled__2024-12-26T00:00:00-03:00, execution_date=20241226T000000, start_date=20241227T095555, end_date=20241227T095556
[2024-12-27T09:55:56.169-0300] {taskinstance.py:340} INFO - ::group::Post task execution logs
[2024-12-27T09:55:56.170-0300] {standard_task_runner.py:124} ERROR - Failed to execute job 564 for task run_my_python_app (Failed to establish connection to any given Docker hosts.; 213)
Traceback (most recent call last):
  File "/home/airflow/.local/lib/python3.12/site-packages/airflow/task/task_runner/standard_task_runner.py", line 117, in _start_by_fork
    ret = args.func(args, dag=self.dag)
          ^^^^^^^^^^^^^^^^^^^^^^^^^^^^^
  File "/home/airflow/.local/lib/python3.12/site-packages/airflow/cli/cli_config.py", line 49, in command
    return func(*args, **kwargs)
           ^^^^^^^^^^^^^^^^^^^^^
  File "/home/airflow/.local/lib/python3.12/site-packages/airflow/utils/cli.py", line 116, in wrapper
    return f(*args, **kwargs)
           ^^^^^^^^^^^^^^^^^^
  File "/home/airflow/.local/lib/python3.12/site-packages/airflow/cli/commands/task_command.py", line 483, in task_run
    task_return_code = _run_task_by_selected_method(args, _dag, ti)
                       ^^^^^^^^^^^^^^^^^^^^^^^^^^^^^^^^^^^^^^^^^^^^
  File "/home/airflow/.local/lib/python3.12/site-packages/airflow/cli/commands/task_command.py", line 256, in _run_task_by_selected_method
    return _run_raw_task(args, ti)
           ^^^^^^^^^^^^^^^^^^^^^^^
  File "/home/airflow/.local/lib/python3.12/site-packages/airflow/cli/commands/task_command.py", line 341, in _run_raw_task
    return ti._run_raw_task(
           ^^^^^^^^^^^^^^^^^
  File "/home/airflow/.local/lib/python3.12/site-packages/airflow/utils/session.py", line 97, in wrapper
    return func(*args, session=session, **kwargs)
           ^^^^^^^^^^^^^^^^^^^^^^^^^^^^^^^^^^^^^^
  File "/home/airflow/.local/lib/python3.12/site-packages/airflow/models/taskinstance.py", line 3005, in _run_raw_task
    return _run_raw_task(
           ^^^^^^^^^^^^^^
  File "/home/airflow/.local/lib/python3.12/site-packages/airflow/models/taskinstance.py", line 273, in _run_raw_task
    TaskInstance._execute_task_with_callbacks(
  File "/home/airflow/.local/lib/python3.12/site-packages/airflow/models/taskinstance.py", line 3159, in _execute_task_with_callbacks
    result = self._execute_task(context, task_orig)
             ^^^^^^^^^^^^^^^^^^^^^^^^^^^^^^^^^^^^^^
  File "/home/airflow/.local/lib/python3.12/site-packages/airflow/models/taskinstance.py", line 3183, in _execute_task
    return _execute_task(self, context, task_orig)
           ^^^^^^^^^^^^^^^^^^^^^^^^^^^^^^^^^^^^^^^
  File "/home/airflow/.local/lib/python3.12/site-packages/airflow/models/taskinstance.py", line 767, in _execute_task
    result = _execute_callable(context=context, **execute_callable_kwargs)
             ^^^^^^^^^^^^^^^^^^^^^^^^^^^^^^^^^^^^^^^^^^^^^^^^^^^^^^^^^^^^^
  File "/home/airflow/.local/lib/python3.12/site-packages/airflow/models/taskinstance.py", line 733, in _execute_callable
    return ExecutionCallableRunner(
           ^^^^^^^^^^^^^^^^^^^^^^^^
  File "/home/airflow/.local/lib/python3.12/site-packages/airflow/utils/operator_helpers.py", line 252, in run
    return self.func(*args, **kwargs)
           ^^^^^^^^^^^^^^^^^^^^^^^^^^
  File "/home/airflow/.local/lib/python3.12/site-packages/airflow/models/baseoperator.py", line 422, in wrapper
    return func(self, *args, **kwargs)
           ^^^^^^^^^^^^^^^^^^^^^^^^^^^
  File "/home/airflow/.local/lib/python3.12/site-packages/airflow/providers/docker/operators/docker.py", line 501, in execute
    if self.force_pull or not self.cli.images(name=self.image):
                              ^^^^^^^^
  File "/home/airflow/.local/lib/python3.12/site-packages/airflow/providers/docker/operators/docker.py", line 375, in cli
    return self.hook.api_client
           ^^^^^^^^^^^^^^^^^^^^
  File "/usr/local/lib/python3.12/functools.py", line 995, in __get__
    val = self.func(instance)
          ^^^^^^^^^^^^^^^^^^^
  File "/home/airflow/.local/lib/python3.12/site-packages/airflow/providers/docker/hooks/docker.py", line 161, in api_client
    raise AirflowException("Failed to establish connection to any given Docker hosts.")
airflow.exceptions.AirflowException: Failed to establish connection to any given Docker hosts.
[2024-12-27T09:55:56.194-0300] {local_task_job_runner.py:266} INFO - Task exited with return code 1
[2024-12-27T09:55:56.240-0300] {taskinstance.py:3895} INFO - 0 downstream tasks scheduled from follow-on schedule check
[2024-12-27T09:55:56.242-0300] {local_task_job_runner.py:245} INFO - ::endgroup::
[2024-12-27T12:01:18.204-0300] {local_task_job_runner.py:123} INFO - ::group::Pre task execution logs
[2024-12-27T12:01:18.236-0300] {taskinstance.py:2613} INFO - Dependencies all met for dep_context=non-requeueable deps ti=<TaskInstance: my_python_app_dag.run_my_python_app scheduled__2024-12-26T00:00:00-03:00 [queued]>
[2024-12-27T12:01:18.248-0300] {taskinstance.py:2613} INFO - Dependencies all met for dep_context=requeueable deps ti=<TaskInstance: my_python_app_dag.run_my_python_app scheduled__2024-12-26T00:00:00-03:00 [queued]>
[2024-12-27T12:01:18.248-0300] {taskinstance.py:2866} INFO - Starting attempt 1 of 2
[2024-12-27T12:01:18.265-0300] {taskinstance.py:2889} INFO - Executing <Task(DockerOperator): run_my_python_app> on 2024-12-26 00:00:00-03:00
[2024-12-27T12:01:18.276-0300] {standard_task_runner.py:104} INFO - Running: ['***', 'tasks', 'run', 'my_python_app_dag', 'run_my_python_app', 'scheduled__2024-12-26T00:00:00-03:00', '--job-id', '336', '--raw', '--subdir', 'DAGS_FOLDER/dag_my-python-app.py', '--cfg-path', '/tmp/tmptc2beud3']
[2024-12-27T12:01:18.279-0300] {standard_task_runner.py:105} INFO - Job 336: Subtask run_my_python_app
[2024-12-27T12:01:18.280-0300] {logging_mixin.py:190} WARNING - /home/***/.local/lib/python3.12/site-packages/***/task/task_runner/standard_task_runner.py:70 DeprecationWarning: This process (pid=1236) is multi-threaded, use of fork() may lead to deadlocks in the child.
[2024-12-27T12:01:18.280-0300] {standard_task_runner.py:72} INFO - Started process 1240 to run task
[2024-12-27T12:01:18.360-0300] {task_command.py:467} INFO - Running <TaskInstance: my_python_app_dag.run_my_python_app scheduled__2024-12-26T00:00:00-03:00 [running]> on host f657cc3f60f7
[2024-12-27T12:01:18.502-0300] {taskinstance.py:3132} INFO - Exporting env vars: AIRFLOW_CTX_DAG_OWNER='***' AIRFLOW_CTX_DAG_ID='my_python_app_dag' AIRFLOW_CTX_TASK_ID='run_my_python_app' AIRFLOW_CTX_EXECUTION_DATE='2024-12-26T00:00:00-03:00' AIRFLOW_CTX_TRY_NUMBER='1' AIRFLOW_CTX_DAG_RUN_ID='scheduled__2024-12-26T00:00:00-03:00'
[2024-12-27T12:01:18.503-0300] {taskinstance.py:731} INFO - ::endgroup::
[2024-12-27T12:01:18.559-0300] {docker.py:379} INFO - Starting docker container from image hello-world:latest
[2024-12-27T12:01:18.905-0300] {docker.py:73} INFO - 
[2024-12-27T12:01:18.906-0300] {docker.py:73} INFO - Hello from Docker!
[2024-12-27T12:01:18.906-0300] {docker.py:73} INFO - This message shows that your installation appears to be working correctly.
[2024-12-27T12:01:18.907-0300] {docker.py:73} INFO - 
[2024-12-27T12:01:18.907-0300] {docker.py:73} INFO - To generate this message, Docker took the following steps:
[2024-12-27T12:01:18.908-0300] {docker.py:73} INFO -  1. The Docker client contacted the Docker daemon.
[2024-12-27T12:01:18.908-0300] {docker.py:73} INFO -  2. The Docker daemon pulled the "hello-world" image from the Docker Hub.
[2024-12-27T12:01:18.908-0300] {docker.py:73} INFO -     (amd64)
[2024-12-27T12:01:18.909-0300] {docker.py:73} INFO -  3. The Docker daemon created a new container from that image which runs the
[2024-12-27T12:01:18.909-0300] {docker.py:73} INFO -     executable that produces the output you are currently reading.
[2024-12-27T12:01:18.910-0300] {docker.py:73} INFO -  4. The Docker daemon streamed that output to the Docker client, which sent it
[2024-12-27T12:01:18.910-0300] {docker.py:73} INFO -     to your terminal.
[2024-12-27T12:01:18.910-0300] {docker.py:73} INFO - 
[2024-12-27T12:01:18.911-0300] {docker.py:73} INFO - To try something more ambitious, you can run an Ubuntu container with:
[2024-12-27T12:01:18.911-0300] {docker.py:73} INFO -  $ docker run -it ubuntu bash
[2024-12-27T12:01:18.912-0300] {docker.py:73} INFO - 
[2024-12-27T12:01:18.913-0300] {docker.py:73} INFO - Share images, automate workflows, and more with a free Docker ID:
[2024-12-27T12:01:18.913-0300] {docker.py:73} INFO -  https://hub.docker.com/
[2024-12-27T12:01:18.914-0300] {docker.py:73} INFO - 
[2024-12-27T12:01:18.915-0300] {docker.py:73} INFO - For more examples and ideas, visit:
[2024-12-27T12:01:18.915-0300] {docker.py:73} INFO -  https://docs.docker.com/get-started/
[2024-12-27T12:01:19.225-0300] {taskinstance.py:340} INFO - ::group::Post task execution logs
[2024-12-27T12:01:19.226-0300] {taskinstance.py:352} INFO - Marking task as SUCCESS. dag_id=my_python_app_dag, task_id=run_my_python_app, run_id=scheduled__2024-12-26T00:00:00-03:00, execution_date=20241226T000000, start_date=20241227T120118, end_date=20241227T120119
[2024-12-27T12:01:19.298-0300] {local_task_job_runner.py:266} INFO - Task exited with return code 0
[2024-12-27T12:01:19.337-0300] {taskinstance.py:3895} INFO - 0 downstream tasks scheduled from follow-on schedule check
[2024-12-27T12:01:19.339-0300] {local_task_job_runner.py:245} INFO - ::endgroup::
